2020-09-22 00:13:29,046 ERROR: Exception on /mywords [GET] [in c:\users\1\web_app1\venv\lib\site-packages\flask\app.py:1891]
Traceback (most recent call last):
  File "c:\users\1\web_app1\venv\lib\site-packages\flask\app.py", line 2447, in wsgi_app
    response = self.full_dispatch_request()
  File "c:\users\1\web_app1\venv\lib\site-packages\flask\app.py", line 1952, in full_dispatch_request
    rv = self.handle_user_exception(e)
  File "c:\users\1\web_app1\venv\lib\site-packages\flask\app.py", line 1821, in handle_user_exception
    reraise(exc_type, exc_value, tb)
  File "c:\users\1\web_app1\venv\lib\site-packages\flask\_compat.py", line 39, in reraise
    raise value
  File "c:\users\1\web_app1\venv\lib\site-packages\flask\app.py", line 1950, in full_dispatch_request
    rv = self.dispatch_request()
  File "c:\users\1\web_app1\venv\lib\site-packages\flask\app.py", line 1936, in dispatch_request
    return self.view_functions[rule.endpoint](**req.view_args)
  File "c:\users\1\web_app1\venv\lib\site-packages\flask_login\utils.py", line 272, in decorated_view
    return func(*args, **kwargs)
  File "C:\Users\1\web_app1\app\routes.py", line 110, in get_mywords
    dictionary_id = current_user.languages.filter_by(language_id = language_id).first().id
UnboundLocalError: local variable 'language_id' referenced before assignment
2020-09-22 00:15:59,074 INFO: Lang startup [in C:\Users\1\web_app1\app\__init__.py:33]
2020-09-22 00:16:00,696 ERROR: Exception on /mywords [GET] [in c:\users\1\web_app1\venv\lib\site-packages\flask\app.py:1891]
Traceback (most recent call last):
  File "c:\users\1\web_app1\venv\lib\site-packages\flask\app.py", line 2447, in wsgi_app
    response = self.full_dispatch_request()
  File "c:\users\1\web_app1\venv\lib\site-packages\flask\app.py", line 1952, in full_dispatch_request
    rv = self.handle_user_exception(e)
  File "c:\users\1\web_app1\venv\lib\site-packages\flask\app.py", line 1821, in handle_user_exception
    reraise(exc_type, exc_value, tb)
  File "c:\users\1\web_app1\venv\lib\site-packages\flask\_compat.py", line 39, in reraise
    raise value
  File "c:\users\1\web_app1\venv\lib\site-packages\flask\app.py", line 1950, in full_dispatch_request
    rv = self.dispatch_request()
  File "c:\users\1\web_app1\venv\lib\site-packages\flask\app.py", line 1936, in dispatch_request
    return self.view_functions[rule.endpoint](**req.view_args)
  File "c:\users\1\web_app1\venv\lib\site-packages\flask_login\utils.py", line 272, in decorated_view
    return func(*args, **kwargs)
  File "C:\Users\1\web_app1\app\routes.py", line 113, in get_mywords
    words = current_user.languages[language_id].words.paginate(
UnboundLocalError: local variable 'language_id' referenced before assignment
2020-09-22 00:16:56,227 INFO: Lang startup [in C:\Users\1\web_app1\app\__init__.py:33]
2020-09-22 00:16:57,741 ERROR: Exception on /mywords [GET] [in c:\users\1\web_app1\venv\lib\site-packages\flask\app.py:1891]
Traceback (most recent call last):
  File "c:\users\1\web_app1\venv\lib\site-packages\flask\app.py", line 2447, in wsgi_app
    response = self.full_dispatch_request()
  File "c:\users\1\web_app1\venv\lib\site-packages\flask\app.py", line 1952, in full_dispatch_request
    rv = self.handle_user_exception(e)
  File "c:\users\1\web_app1\venv\lib\site-packages\flask\app.py", line 1821, in handle_user_exception
    reraise(exc_type, exc_value, tb)
  File "c:\users\1\web_app1\venv\lib\site-packages\flask\_compat.py", line 39, in reraise
    raise value
  File "c:\users\1\web_app1\venv\lib\site-packages\flask\app.py", line 1950, in full_dispatch_request
    rv = self.dispatch_request()
  File "c:\users\1\web_app1\venv\lib\site-packages\flask\app.py", line 1936, in dispatch_request
    return self.view_functions[rule.endpoint](**req.view_args)
  File "c:\users\1\web_app1\venv\lib\site-packages\flask_login\utils.py", line 272, in decorated_view
    return func(*args, **kwargs)
  File "C:\Users\1\web_app1\app\routes.py", line 113, in get_mywords
    words = current_user.languages[dictionary_id].words.paginate(
  File "c:\users\1\web_app1\venv\lib\site-packages\sqlalchemy\orm\dynamic.py", line 323, in __getitem__
    return self._clone(sess).__getitem__(index)
  File "c:\users\1\web_app1\venv\lib\site-packages\sqlalchemy\orm\query.py", line 3154, in __getitem__
    return list(self[item : item + 1])[0]
IndexError: list index out of range
2020-09-22 00:50:51,184 INFO: Lang startup [in C:\Users\1\web_app1\app\__init__.py:33]
2020-09-22 00:50:52,931 ERROR: Exception on /mywords [GET] [in c:\users\1\web_app1\venv\lib\site-packages\flask\app.py:1891]
Traceback (most recent call last):
  File "c:\users\1\web_app1\venv\lib\site-packages\flask\app.py", line 2447, in wsgi_app
    response = self.full_dispatch_request()
  File "c:\users\1\web_app1\venv\lib\site-packages\flask\app.py", line 1952, in full_dispatch_request
    rv = self.handle_user_exception(e)
  File "c:\users\1\web_app1\venv\lib\site-packages\flask\app.py", line 1821, in handle_user_exception
    reraise(exc_type, exc_value, tb)
  File "c:\users\1\web_app1\venv\lib\site-packages\flask\_compat.py", line 39, in reraise
    raise value
  File "c:\users\1\web_app1\venv\lib\site-packages\flask\app.py", line 1950, in full_dispatch_request
    rv = self.dispatch_request()
  File "c:\users\1\web_app1\venv\lib\site-packages\flask\app.py", line 1936, in dispatch_request
    return self.view_functions[rule.endpoint](**req.view_args)
  File "c:\users\1\web_app1\venv\lib\site-packages\flask_login\utils.py", line 272, in decorated_view
    return func(*args, **kwargs)
  File "C:\Users\1\web_app1\app\routes.py", line 112, in get_mywords
    language = Language.query.filter_by(id = dictionary_id).first()
UnboundLocalError: local variable 'dictionary_id' referenced before assignment
2020-09-22 00:51:47,441 INFO: Lang startup [in C:\Users\1\web_app1\app\__init__.py:33]
2020-09-22 00:51:57,173 ERROR: Exception on /mywords [GET] [in c:\users\1\web_app1\venv\lib\site-packages\flask\app.py:1891]
Traceback (most recent call last):
  File "c:\users\1\web_app1\venv\lib\site-packages\flask\app.py", line 2447, in wsgi_app
    response = self.full_dispatch_request()
  File "c:\users\1\web_app1\venv\lib\site-packages\flask\app.py", line 1952, in full_dispatch_request
    rv = self.handle_user_exception(e)
  File "c:\users\1\web_app1\venv\lib\site-packages\flask\app.py", line 1821, in handle_user_exception
    reraise(exc_type, exc_value, tb)
  File "c:\users\1\web_app1\venv\lib\site-packages\flask\_compat.py", line 39, in reraise
    raise value
  File "c:\users\1\web_app1\venv\lib\site-packages\flask\app.py", line 1950, in full_dispatch_request
    rv = self.dispatch_request()
  File "c:\users\1\web_app1\venv\lib\site-packages\flask\app.py", line 1936, in dispatch_request
    return self.view_functions[rule.endpoint](**req.view_args)
  File "c:\users\1\web_app1\venv\lib\site-packages\flask_login\utils.py", line 272, in decorated_view
    return func(*args, **kwargs)
  File "C:\Users\1\web_app1\app\routes.py", line 107, in get_mywords
    dictionaryForm.foreign_languages.choices = [language for language in languages]
NameError: name 'languages' is not defined
2020-09-22 00:52:25,029 INFO: Lang startup [in C:\Users\1\web_app1\app\__init__.py:33]
2020-09-22 00:52:26,860 ERROR: Exception on /mywords [GET] [in c:\users\1\web_app1\venv\lib\site-packages\flask\app.py:1891]
Traceback (most recent call last):
  File "c:\users\1\web_app1\venv\lib\site-packages\flask\app.py", line 2447, in wsgi_app
    response = self.full_dispatch_request()
  File "c:\users\1\web_app1\venv\lib\site-packages\flask\app.py", line 1952, in full_dispatch_request
    rv = self.handle_user_exception(e)
  File "c:\users\1\web_app1\venv\lib\site-packages\flask\app.py", line 1821, in handle_user_exception
    reraise(exc_type, exc_value, tb)
  File "c:\users\1\web_app1\venv\lib\site-packages\flask\_compat.py", line 39, in reraise
    raise value
  File "c:\users\1\web_app1\venv\lib\site-packages\flask\app.py", line 1950, in full_dispatch_request
    rv = self.dispatch_request()
  File "c:\users\1\web_app1\venv\lib\site-packages\flask\app.py", line 1936, in dispatch_request
    return self.view_functions[rule.endpoint](**req.view_args)
  File "c:\users\1\web_app1\venv\lib\site-packages\flask_login\utils.py", line 272, in decorated_view
    return func(*args, **kwargs)
  File "C:\Users\1\web_app1\app\routes.py", line 113, in get_mywords
    language = Language.query.filter_by(id = dictionary_id).first()
UnboundLocalError: local variable 'dictionary_id' referenced before assignment
2020-09-22 00:52:51,664 INFO: Lang startup [in C:\Users\1\web_app1\app\__init__.py:33]
2020-09-22 00:53:31,082 INFO: Lang startup [in C:\Users\1\web_app1\app\__init__.py:33]
